Traceback (most recent call last):
  File "/opt/hostedtoolcache/Python/3.8.18/x64/lib/python3.8/site-packages/jupyter_cache/executors/utils.py", line 58, in single_nb_execution
    executenb(
  File "/opt/hostedtoolcache/Python/3.8.18/x64/lib/python3.8/site-packages/nbclient/client.py", line 1305, in execute
    return NotebookClient(nb=nb, resources=resources, km=km, **kwargs).execute()
  File "/opt/hostedtoolcache/Python/3.8.18/x64/lib/python3.8/site-packages/jupyter_core/utils/__init__.py", line 165, in wrapped
    return loop.run_until_complete(inner)
  File "/opt/hostedtoolcache/Python/3.8.18/x64/lib/python3.8/asyncio/base_events.py", line 616, in run_until_complete
    return future.result()
  File "/opt/hostedtoolcache/Python/3.8.18/x64/lib/python3.8/site-packages/nbclient/client.py", line 705, in async_execute
    await self.async_execute_cell(
  File "/opt/hostedtoolcache/Python/3.8.18/x64/lib/python3.8/site-packages/nbclient/client.py", line 1058, in async_execute_cell
    await self._check_raise_for_error(cell, cell_index, exec_reply)
  File "/opt/hostedtoolcache/Python/3.8.18/x64/lib/python3.8/site-packages/nbclient/client.py", line 914, in _check_raise_for_error
    raise CellExecutionError.from_cell_and_msg(cell, exec_reply_content)
nbclient.exceptions.CellExecutionError: An error occurred while executing the following cell:
------------------
import math
weird_numbers = make_array(-2, math.floor(12.6), 3, 5**math.ceil(5.3)) # SOLUTION
weird_numbers
------------------


[0;31m---------------------------------------------------------------------------[0m
[0;31mNameError[0m                                 Traceback (most recent call last)
Cell [0;32mIn[1], line 2[0m
[1;32m      1[0m [38;5;28;01mimport[39;00m [38;5;21;01mmath[39;00m
[0;32m----> 2[0m weird_numbers [38;5;241m=[39m [43mmake_array[49m([38;5;241m-[39m[38;5;241m2[39m, math[38;5;241m.[39mfloor([38;5;241m12.6[39m), [38;5;241m3[39m, [38;5;241m5[39m[38;5;241m*[39m[38;5;241m*[39mmath[38;5;241m.[39mceil([38;5;241m5.3[39m)) [38;5;66;03m# SOLUTION[39;00m
[1;32m      3[0m weird_numbers

[0;31mNameError[0m: name 'make_array' is not defined

